[2025-04-17 20:27:14] [INFO    ] discord.client: logging in using static token
[2025-04-17 20:27:16] [INFO    ] discord.gateway: Shard ID None has connected to Gateway (Session ID: 4b4e6d3a71a00a06c914b55142ff94fd).
[2025-04-17 20:27:22] [INFO    ] discord.voice_state: Connecting to voice...
[2025-04-17 20:27:22] [INFO    ] discord.voice_state: Starting voice handshake... (connection attempt 1)
[2025-04-17 20:27:22] [INFO    ] discord.voice_state: Voice handshake complete. Endpoint found: us-east124.discord.media
[2025-04-17 20:27:23] [INFO    ] discord.voice_state: Voice connection complete.
[2025-04-17 20:27:45] [ERROR   ] discord.app_commands.tree: Ignoring exception in command 'play'
Traceback (most recent call last):
  File "c:\Users\Spencer\Documents\GitHub\Cyan\modules\music.py", line 74, in play
    guild.voice_client.play(player, after=lambda e: print(f"Player error: {e}") if e else None)
    ~~~~~~~~~~~~~~~~~~~~~~~^^^^^^^^^^^^^^^^^^^^^^^^^^^^^^^^^^^^^^^^^^^^^^^^^^^^^^^^^^^^^^^^^^^^
  File "C:\Users\Spencer\AppData\Local\Programs\Python\Python313\Lib\site-packages\discord\voice_client.py", line 500, in play
    raise ClientException('Already playing audio.')
discord.errors.ClientException: Already playing audio.

During handling of the above exception, another exception occurred:

Traceback (most recent call last):
  File "C:\Users\Spencer\AppData\Local\Programs\Python\Python313\Lib\site-packages\discord\app_commands\commands.py", line 857, in _do_call
    return await self._callback(self.binding, interaction, **params)  # type: ignore
           ^^^^^^^^^^^^^^^^^^^^^^^^^^^^^^^^^^^^^^^^^^^^^^^^^^^^^^^^^
  File "c:\Users\Spencer\Documents\GitHub\Cyan\modules\music.py", line 78, in play
    await interaction.response.send_message(f"There was an error ðŸ˜”")
  File "C:\Users\Spencer\AppData\Local\Programs\Python\Python313\Lib\site-packages\discord\interactions.py", line 976, in send_message
    raise InteractionResponded(self._parent)
discord.errors.InteractionResponded: This interaction has already been responded to before

The above exception was the direct cause of the following exception:

Traceback (most recent call last):
  File "C:\Users\Spencer\AppData\Local\Programs\Python\Python313\Lib\site-packages\discord\app_commands\tree.py", line 1310, in _call
    await command._invoke_with_namespace(interaction, namespace)
  File "C:\Users\Spencer\AppData\Local\Programs\Python\Python313\Lib\site-packages\discord\app_commands\commands.py", line 883, in _invoke_with_namespace
    return await self._do_call(interaction, transformed_values)
           ^^^^^^^^^^^^^^^^^^^^^^^^^^^^^^^^^^^^^^^^^^^^^^^^^^^^
  File "C:\Users\Spencer\AppData\Local\Programs\Python\Python313\Lib\site-packages\discord\app_commands\commands.py", line 876, in _do_call
    raise CommandInvokeError(self, e) from e
discord.app_commands.errors.CommandInvokeError: Command 'play' raised an exception: InteractionResponded: This interaction has already been responded to before
[2025-04-17 20:27:45] [INFO    ] discord.player: ffmpeg process 19952 has not terminated. Waiting to terminate...
[2025-04-17 20:27:45] [INFO    ] discord.player: ffmpeg process 19952 should have terminated with a return code of 1.
[2025-04-17 20:27:56] [INFO    ] discord.player: ffmpeg process 16984 successfully terminated with return code of 0.
[2025-04-17 20:28:49] [INFO    ] discord.player: ffmpeg process 3620 successfully terminated with return code of 0.
[2025-04-17 20:29:56] [INFO    ] discord.player: ffmpeg process 6056 successfully terminated with return code of 0.
[2025-04-17 21:01:13] [INFO    ] discord.gateway: Shard ID None has successfully RESUMED session 4b4e6d3a71a00a06c914b55142ff94fd.
